Workbook

Sheet publich holiday

Sheet How to print
A1: เมื่อทำงานครบเดือนแล้ว ให้ทำการ พิมพ์ Timesheet ในเดือนนั้นๆ เพื่อให้ Project Manager เซ็นอนุมัติ จากนั้นจึงค่อยส่งไปที่บัญชีเพื่อตรวจสอบความถูกต้อง
A2: วิธีการพิมพ์ทำได้ง่ายดังนี้
A3: 1) เลือก File
A4: 2) Save as
A5: 2.1) กำหนดชื่อไฟล์ ระบุเดือน
A6: 2.2) กำหนด file type เป็น PDF
A7: 2.3) กด Save

Sheet January
A1: รายงานการปฏิบัติงาน
A2: บริษัท ไอที ดี จำกัด
C3: ประจำวันที่ | D3: =DAY(A8)&" "&CHOOSE(MONTH(A8),"มกราคม","กุมภาพันธ์","มีนาคม","เมษายน","พฤษภาคม","มิถุนายน","กรกฎาคม","สิงหาคม","กันยายน","ตุลาคม","พฤศจิกายน","ธันวาคม")&" "&YEAR(A8)+543&" ถึง "&DAY(A38)&" "&CHOOSE(MONTH(A38),"มกราคม","กุมภาพันธ์","มีนาคม","เมษายน","พฤษภาคม","มิถุนายน","กรกฎาคม","สิงหาคม","กันยายน","ตุลาคม","พฤศจิกายน","ธันวาคม")&" "&YEAR(A38)+543 -> 1 มกราคม 2569 ถึง 31 มกราคม 2569
A5: ชื่อ - นามสกุล | B5: บุรพล อัศววิรุฬห์ฤทธิ์ | D5: โครงการ | E5: Fast Track
A7: วันที่ | B7: การปฎิบัติงาน | C7: รหัสงาน | D7: ประเภทงาน | E7: รายละเอียดของงานที่ทำ
A8: 46023 | B8: วันหยุดนักขัตฤกษ์
A9: =A8+1 -> 46024
A10: =A9+1 -> 46025 | B10: วันเสาร์
A11: =A10+1 -> 46026 | B11: วันอาทิตย์
A12: =A11+1 -> 46027
A13: =A12+1 -> 46028
A14: =A13+1 -> 46029
A15: =A14+1 -> 46030
A16: =A15+1 -> 46031
A17: =A16+1 -> 46032 | B17: วันเสาร์
A18: =A17+1 -> 46033 | B18: วันอาทิตย์
A19: =A18+1 -> 46034
A20: =A19+1 -> 46035
A21: =A20+1 -> 46036
A22: =A21+1 -> 46037
A23: =A22+1 -> 46038
A24: =A23+1 -> 46039 | B24: วันเสาร์
A25: =A24+1 -> 46040 | B25: วันอาทิตย์
A26: =A25+1 -> 46041
A27: =A26+1 -> 46042
A28: =A27+1 -> 46043
A29: =A28+1 -> 46044
A30: =A29+1 -> 46045
A31: =A30+1 -> 46046 | B31: วันเสาร์
A32: =A31+1 -> 46047 | B32: วันอาทิตย์
A33: =A32+1 -> 46048
A34: =A33+1 -> 46049
A35: =A34+1 -> 46050
A36: =A35+1 -> 46051
A37: =A36+1 -> 46052
A38: =A37+1 -> 46053 | B38: วันเสาร์
A39: รวมทั้งสิ้น | C39: =SUM(C8:C38) -> 0 | D39: =SUM(D8:D38) -> 0
B40: วันเข้าปฎิบัตงาน | C40: =COUNTIF($B$8:$B$38, "เข้าปฎิบัติงาน") -> 0 | D40: วันหยุด | E40: =SUM(COUNTIF($B$8:$B$38, {"วันเสาร์","วันอาทิตย์","วันหยุดนักขัตฤกษ์"})) -> 10
B41: วันไม่เข้าปฎิบัตงาน | C41: =COUNTIF($B$8:$B$38, "ไม่เข้าปฎิบัติงาน") -> 0 | D41: อื่นๆ | E41: =COUNTIF($B$8:$B$38, "อื่นๆ โปรดระบุรายละเอียด ") -> 0
A42: ลงชื่อ................................................ | F42: ลงชื่อ ...............................................
...

Sheet June
A1: =January!A1 -> รายงานการปฏิบัติงาน
A2: =January!A2 -> บริษัท ไอที ดี จำกัด
C3: ประจำวันที่ | D3: =DAY(A8)&" "&CHOOSE(MONTH(A8),"มกราคม","กุมภาพันธ์","มีนาคม","เมษายน","พฤษภาคม","มิถุนายน","กรกฎาคม","สิงหาคม","กันยายน","ตุลาคม","พฤศจิกายน","ธันวาคม")&" "&YEAR(A8)+543&" ถึง "&DAY(A37)&" "&CHOOSE(MONTH(A37),"มกราคม","กุมภาพันธ์","มีนาคม","เมษายน","พฤษภาคม","มิถุนายน","กรกฎาคม","สิงหาคม","กันยายน","ตุลาคม","พฤศจิกายน","ธันวาคม")&" "&YEAR(A37)+543 -> 1 มิถุนายน 2569 ถึง 30 มิถุนายน 2569
A5: ชื่อ - นามสกุล | B5: =January!B5 -> บุรพล อัศววิรุฬห์ฤทธิ์ | D5: โครงการ | E5: =January!E5 -> Fast Track
A7: วันที่ | B7: การปฎิบัติงาน | C7: รหัสงาน | D7: ประเภทงาน | E7: รายละเอียดของงานที่ทำ
A8: 46174 | B8: วันหยุดนักขัตฤกษ์
A9: =A8+1 -> 46175 | B9: เข้าปฎิบัติงาน | C9: FTRV032 | D9: Analysis: เริ่มศึกษาโครงการ Fast Track Revamp 2024 Backend, review scope migration .NET 4.x -> .NET 8 และโครงสร้าง solution/API/service/repository | E9: เริ่มศึกษาโครงการ Fast Track Revamp 2024 Backend, review scope migration .NET 4.x -> .NET 8 และโครงสร้าง solution/API/service/repository
A10: =A9+1 -> 46176 | B10: วันหยุดนักขัตฤกษ์
A11: =A10+1 -> 46177 | B11: เข้าปฎิบัติงาน | C11: FTRV032 | D11: Analysis: วิเคราะห์ flow AppSnapshot Submission เดิม, ตรวจ controller/service/repository และจุดเชื่อมต่อ legacy mapping | E11: วิเคราะห์ flow AppSnapshot Submission เดิม, ตรวจ controller/service/repository และจุดเชื่อมต่อ legacy mapping
A12: =A11+1 -> 46178 | B12: เข้าปฎิบัติงาน | C12: FTRV032 | D12: Analysis: ตรวจ reducer.js, SuperConverter และ legacy flat key contract เพื่อหา root cause ของ mapping mismatch | E12: ตรวจ reducer.js, SuperConverter และ legacy flat key contract เพื่อหา root cause ของ mapping mismatch
A13: =A12+1 -> 46179 | B13: วันเสาร์
A14: =A13+1 -> 46180 | B14: วันอาทิตย์
A15: =A14+1 -> 46181 | B15: เข้าปฎิบัติงาน | C15: FTRV032 | D15: Development: ทำ golden mapper comparison และเพิ่ม test coverage สำหรับ reducer/mapper เพื่อพิสูจน์ expected legacy contract | E15: ทำ golden mapper comparison และเพิ่ม test coverage สำหรับ reducer/mapper เพื่อพิสูจน์ expected legacy contract
A16: =A15+1 -> 46182 | B16: เข้าปฎิบัติงาน | C16: FTRV032 | D16: Development: ปรับ dedicated Submission DTO/transformer/normalizer และ validate output ให้เข้ากับ SuperConverter/legacy payload | E16: ปรับ dedicated Submission DTO/transformer/normalizer และ validate output ให้เข้ากับ SuperConverter/legacy payload
A17: =A16+1 -> 46183 | B17: เข้าปฎิบัติงาน | C17: FTRV032 | D17: Analysis: ตรวจ DB contract ของ AppInfoRevamp และ field lineage เบื้องต้น legacy ↔ revamp พร้อมบันทึก gap | E17: ตรวจ DB contract ของ AppInfoRevamp และ field lineage เบื้องต้น legacy ↔ revamp พร้อมบันทึก gap
A18: =A17+1 -> 46184 | B18: เข้าปฎิบัติงาน | C18: FTRV032 | D18: Testing: รัน build/test บน macOS, ตรวจ SDK/global.json และจัดทำ evidence/roadmap status สำหรับ runtime readiness | E18: รัน build/test บน macOS, ตรวจ SDK/global.json และจัดทำ evidence/roadmap status สำหรับ runtime readiness
A19: =A18+1 -> 46185 | B19: เข้าปฎิบัติงาน | C19: FTRV032 | D19: Documentation: จัดทำ/อัปเดต FTR knowledge base, roadmap dashboard และ guardrail Runtime OFF / Activation NO-GO | E19: จัดทำ/อัปเดต FTR knowledge base, roadmap dashboard และ guardrail Runtime OFF / Activation NO-GO
A20: =A19+1 -> 46186 | B20: วันเสาร์
A21: =A20+1 -> 46187 | B21: วันอาทิตย์
A22: =A21+1 -> 46188 | B22: เข้าปฎิบัติงาน | C22: FTRV032 | D22: Development: พัฒนาและตรวจ Step 3 AgentInfo enrichment path: agent lookup, license eligibility, OJT lookup และ unit consistency | E22: พัฒนาและตรวจ Step 3 AgentInfo enrichment path: agent lookup, license eligibility, OJT lookup และ unit consistency
A23: =A22+1 -> 46189 | B23: เข้าปฎิบัติงาน | C23: FTRV032 | D23: Testing: ทำ Windows runtime verification/negative cases สำหรับ Step 3 และบันทึก evidence โดยไม่เปิด gateway/external runtime | E23: ทำ Windows runtime verification/negative cases สำหรับ Step 3 และบันทึก evidence โดยไม่เปิด gateway/external runtime
A24: =A23+1 -> 46190 | B24: เข้าปฎิบัติงาน | C24: FTRV032 | D24: Analysis: วิเคราะห์ Step 10/11 UAT boundary, process-history gate, gateway/queue/WCF dependency และ owner pending items | E24: วิเคราะห์ Step 10/11 UAT boundary, process-history gate, gateway/queue/WCF dependency และ owner pending items
A25: =A24+1 -> 46191 | B25: เข้าปฎิบัติงาน | C25: FTRV032 | D25: Documentation: ปรับ roadmap/AI-Brain และ owner escalation docs สำหรับ legacy-first UAT, runtime OFF และ activation NO-GO | E25: ปรับ roadmap/AI-Brain และ owner escalation docs สำหรับ legacy-first UAT, runtime OFF และ activation NO-GO
A26: =A25+1 -> 46192 | B26: เข้าปฎิบัติงาน | C26: FTRV032 | D26: Documentation: สรุป/ปรับ dashboard focus cards และ owner alignment สำหรับ Step 10-12 พร้อมบันทึกสถานะ runtime OFF / activation NO-GO | E26: สรุป/ปรับ dashboard focus cards และ owner alignment สำหรับ Step 10-12 พร้อมบันทึกสถานะ runtime OFF / activation NO-GO
A27: =A26+1 -> 46193 | B27: วันเสาร์
A28: =A27+1 -> 46194 | B28: วันอาทิตย์
A29: =A28+1 -> 46195 | B29: เข้าปฎิบัติงาน | C29: FTRV032 | D29: Analysis: สรุป owner decision OLAE Phase B2: target OLAE_RV_2024, legacy OLAE เป็น reference only และกำหนด SP adapter path | E29: สรุป owner decision OLAE Phase B2: target OLAE_RV_2024, legacy OLAE เป็น reference only และกำหนด SP adapter path
A30: =A29+1 -> 46196 | B30: เข้าปฎิบัติงาน | C30: FTRV032 | D30: Development: พัฒนา OLAE SP handoff adapter boundary, no-DB evidence builders และ legacy parity matrix สำหรับ application/payment spine | E30: พัฒนา OLAE SP handoff adapter boundary, no-DB evidence builders และ legacy parity matrix สำหรับ application/payment spine
A31: =A30+1 -> 46197 | B31: เข้าปฎิบัติงาน | C31: FTRV032 | D31: Testing: ทำ OLAE proof tooling: Windows NoDb smoke, read-only preflight, C# write-proof harness และ UI runner guard | E31: ทำ OLAE proof tooling: Windows NoDb smoke, read-only preflight, C# write-proof harness และ UI runner guard
A32: =A31+1 -> 46198 | B32: เข้าปฎิบัติงาน | C32: FTRV032 | D32: Testing: ทำ Level 2 rollback structural proof, table verification และเตรียม Level 3 committed UAT proof gate | E32: ทำ Level 2 rollback structural proof, table verification และเตรียม Level 3 committed UAT proof gate
A33: =A32+1 -> 46199 | B33: เข้าปฎิบัติงาน | C33: FTRV032 | D33: Proof: รัน Level 3 committed UAT structural proof 1 record ใน OLAE_RV_2024: REF_NO FTRV032-144158, readback 4/4 PASS; ไม่เปิด runtime/external send | E33: รัน Level 3 committed UAT structural proof 1 record ใน OLAE_RV_2024: REF_NO FTRV032-144158, readback 4/4 PASS; ไม่เปิด runtime/external send
A34: =A33+1 -> 46200 | B34: วันเสาร์
A35: =A34+1 -> 46201 | B35: วันอาทิตย์
A36: =A35+1 -> 46202 | B36: เข้าปฎิบัติงาน | C36: FTRV032 | D36: Analysis/Documentation: ปรับ OLAE/AS400 SP Chain Review UI ให้สอดคล้องหลักฐานล่าสุด: dependency closure, CLIENT deferred และ non-renewal OL/TA readiness | E36: ปรับ OLAE/AS400 SP Chain Review UI ให้สอดคล้องหลักฐานล่าสุด: dependency closure, CLIENT deferred renewal-only gap, non-renewal OL/TA READY_FOR_OWNER_REVIEW และ guardrail Runtime OFF / Activation NO-GO
A37: =A36+1 -> 46203 | B37: เข้าปฎิบัติงาน | C37: FTRV032 | D37: Planning/Development: วางแผน C# Revamp -> OLAE non-renewal OL/TA และออกแบบ FTR Evidence Flow Explorer สำหรับ visualize SP flow/evidence/risk แบบ local-first | E37: วางแผนงาน C# Revamp -> OLAE non-renewal OL/TA แบบ runtime gated พร้อมออกแบบ FTR Evidence Flow Explorer สำหรับแสดง SP chain, dependency, table impact, evidence status และ risk classification
B39: วันเข้าปฎิบัตงาน | C39: =COUNTIF($B$8:$B$37, "เข้าปฎิบัติงาน") -> 20 | D39: วันหยุด | E39: =SUM(COUNTIF($B$8:$B$37, {"วันเสาร์","วันอาทิตย์","วันหยุดนักขัตฤกษ์"})) -> 10
B40: วันไม่เข้าปฎิบัตงาน | C40: =COUNTIF($B$8:$B$37, "ไม่เข้าปฎิบัติงาน") -> 0 | D40: อื่นๆ | E40: =COUNTIF($B$8:$B$37, "อื่นๆ โปรดระบุรายละเอียด ") -> 0
D43: Review by | G43: Approve by
A44: ลงชื่อ ............................................... | D44: ลงชื่อ ............................................... | G44: ลงชื่อ ...............................................
A45: =B5 -> บุรพล อัศววิรุฬห์ฤทธิ์ | D45: =January!$F43 -> คุณสายฝน นามกูล | G45: =January!$H43 -> คุณอัจฉรา ชัยภูมิ
...

Sheet July
A1: =January!A1 -> รายงานการปฏิบัติงาน
A2: =January!A2 -> บริษัท ไอที ดี จำกัด
C3: ประจำวันที่ | D3: =DAY(A8)&" "&CHOOSE(MONTH(A8),"มกราคม","กุมภาพันธ์","มีนาคม","เมษายน","พฤษภาคม","มิถุนายน","กรกฎาคม","สิงหาคม","กันยายน","ตุลาคม","พฤศจิกายน","ธันวาคม")&" "&YEAR(A8)+543&" ถึง "&DAY(A38)&" "&CHOOSE(MONTH(A38),"มกราคม","กุมภาพันธ์","มีนาคม","เมษายน","พฤษภาคม","มิถุนายน","กรกฎาคม","สิงหาคม","กันยายน","ตุลาคม","พฤศจิกายน","ธันวาคม")&" "&YEAR(A38)+543 -> 1 กรกฎาคม 2569 ถึง 31 กรกฎาคม 2569
A5: ชื่อ - นามสกุล | B5: =January!B5 -> บุรพล อัศววิรุฬห์ฤทธิ์ | D5: โครงการ | E5: =January!E5 -> Fast Track
A7: วันที่ | B7: การปฎิบัติงาน | C7: รหัสงาน | D7: ประเภทงาน | E7: รายละเอียดของงานที่ทำ
A8: 46204
A9: =A8+1 -> 46205
A10: =A9+1 -> 46206
A11: =A10+1 -> 46207 | B11: วันเสาร์
A12: =A11+1 -> 46208 | B12: วันอาทิตย์
A13: =A12+1 -> 46209
A14: =A13+1 -> 46210
A15: =A14+1 -> 46211
A16: =A15+1 -> 46212
A17: =A16+1 -> 46213
A18: =A17+1 -> 46214 | B18: วันเสาร์
A19: =A18+1 -> 46215 | B19: วันอาทิตย์
A20: =A19+1 -> 46216
A21: =A20+1 -> 46217
A22: =A21+1 -> 46218
A23: =A22+1 -> 46219
A24: =A23+1 -> 46220
A25: =A24+1 -> 46221 | B25: วันเสาร์
A26: =A25+1 -> 46222 | B26: วันอาทิตย์
A27: =A26+1 -> 46223
A28: =A27+1 -> 46224
A29: =A28+1 -> 46225
A30: =A29+1 -> 46226
A31: =A30+1 -> 46227
A32: =A31+1 -> 46228 | B32: วันเสาร์
A33: =A32+1 -> 46229 | B33: วันอาทิตย์
A34: =A33+1 -> 46230
A35: =A34+1 -> 46231 | B35: วันหยุดนักขัตฤกษ์
A36: =A35+1 -> 46232 | B36: วันหยุดนักขัตฤกษ์
A37: =A36+1 -> 46233
A38: =A37+1 -> 46234
B40: วันเข้าปฎิบัตงาน | C40: =COUNTIF($B$8:$B$38, "เข้าปฎิบัติงาน") -> 0 | D40: วันหยุด | E40: =SUM(COUNTIF($B$8:$B$38, {"วันเสาร์","วันอาทิตย์","วันหยุดนักขัตฤกษ์"})) -> 10
B41: วันไม่เข้าปฎิบัตงาน | C41: =COUNTIF($B$8:$B$38, "ไม่เข้าปฎิบัติงาน") -> 0 | D41: อื่นๆ | E41: =COUNTIF($B$8:$B$38, "อื่นๆ โปรดระบุรายละเอียด ") -> 0
D43: Review by | G43: Approve by
A44: ลงชื่อ ............................................... | D44: ลงชื่อ ............................................... | G44: ลงชื่อ ...............................................
...

Sheet August
A1: =January!A1 -> รายงานการปฏิบัติงาน
A2: =January!A2 -> บริษัท ไอที ดี จำกัด
C3: ประจำวันที่ | D3: =DAY(A8)&" "&CHOOSE(MONTH(A8),"มกราคม","กุมภาพันธ์","มีนาคม","เมษายน","พฤษภาคม","มิถุนายน","กรกฎาคม","สิงหาคม","กันยายน","ตุลาคม","พฤศจิกายน","ธันวาคม")&" "&YEAR(A8)+543&" ถึง "&DAY(A38)&" "&CHOOSE(MONTH(A38),"มกราคม","กุมภาพันธ์","มีนาคม","เมษายน","พฤษภาคม","มิถุนายน","กรกฎาคม","สิงหาคม","กันยายน","ตุลาคม","พฤศจิกายน","ธันวาคม")&" "&YEAR(A38)+543 -> 1 สิงหาคม 2569 ถึง 31 สิงหาคม 2569
A5: ชื่อ - นามสกุล | B5: =January!B5 -> บุรพล อัศววิรุฬห์ฤทธิ์ | D5: โครงการ | E5: =January!E5 -> Fast Track
A7: วันที่ | B7: การปฎิบัติงาน | C7: รหัสงาน | D7: ประเภทงาน | E7: รายละเอียดของงานที่ทำ
A8: 46235 | B8: วันเสาร์
A9: =A8+1 -> 46236 | B9: วันอาทิตย์
A10: =A9+1 -> 46237
A11: =A10+1 -> 46238
A12: =A11+1 -> 46239
A13: =A12+1 -> 46240
A14: =A13+1 -> 46241
A15: =A14+1 -> 46242 | B15: วันเสาร์
A16: =A15+1 -> 46243 | B16: วันอาทิตย์
A17: =A16+1 -> 46244
A18: =A17+1 -> 46245
A19: =A18+1 -> 46246 | B19: วันหยุดนักขัตฤกษ์
A20: =A19+1 -> 46247
A21: =A20+1 -> 46248
A22: =A21+1 -> 46249 | B22: วันเสาร์
A23: =A22+1 -> 46250 | B23: วันอาทิตย์
A24: =A23+1 -> 46251
A25: =A24+1 -> 46252
A26: =A25+1 -> 46253
A27: =A26+1 -> 46254
A28: =A27+1 -> 46255
A29: =A28+1 -> 46256 | B29: วันเสาร์
A30: =A29+1 -> 46257 | B30: วันอาทิตย์
A31: =A30+1 -> 46258
A32: =A31+1 -> 46259
A33: =A32+1 -> 46260
A34: =A33+1 -> 46261
A35: =A34+1 -> 46262
A36: =A35+1 -> 46263 | B36: วันเสาร์
A37: =A36+1 -> 46264 | B37: วันอาทิตย์
A38: =A37+1 -> 46265
B40: วันเข้าปฎิบัตงาน | C40: =COUNTIF($B$8:$B$38, "เข้าปฎิบัติงาน") -> 0 | D40: วันหยุด | E40: =SUM(COUNTIF($B$8:$B$38, {"วันเสาร์","วันอาทิตย์","วันหยุดนักขัตฤกษ์"})) -> 11
B41: วันไม่เข้าปฎิบัตงาน | C41: =COUNTIF($B$8:$B$38, "ไม่เข้าปฎิบัติงาน") -> 0 | D41: อื่นๆ | E41: =COUNTIF($B$8:$B$38, "อื่นๆ โปรดระบุรายละเอียด ") -> 0
D43: Review by | G43: Approve by
A44: ลงชื่อ ............................................... | D44: ลงชื่อ ............................................... | G44: ลงชื่อ ...............................................
...

Sheet September
A1: =January!A1 -> รายงานการปฏิบัติงาน
A2: =January!A2 -> บริษัท ไอที ดี จำกัด
C3: ประจำวันที่ | D3: =DAY(A8)&" "&CHOOSE(MONTH(A8),"มกราคม","กุมภาพันธ์","มีนาคม","เมษายน","พฤษภาคม","มิถุนายน","กรกฎาคม","สิงหาคม","กันยายน","ตุลาคม","พฤศจิกายน","ธันวาคม")&" "&YEAR(A8)+543&" ถึง "&DAY(A37)&" "&CHOOSE(MONTH(A37),"มกราคม","กุมภาพันธ์","มีนาคม","เมษายน","พฤษภาคม","มิถุนายน","กรกฎาคม","สิงหาคม","กันยายน","ตุลาคม","พฤศจิกายน","ธันวาคม")&" "&YEAR(A37)+543 -> 1 กันยายน 2569 ถึง 30 กันยายน 2569
A5: ชื่อ - นามสกุล | B5: =January!B5 -> บุรพล อัศววิรุฬห์ฤทธิ์ | D5: โครงการ | E5: =January!E5 -> Fast Track
A7: วันที่ | B7: การปฎิบัติงาน | C7: รหัสงาน | D7: ประเภทงาน | E7: รายละเอียดของงานที่ทำ
A8: 46266
A9: =A8+1 -> 46267
A10: =A9+1 -> 46268
A11: =A10+1 -> 46269
A12: =A11+1 -> 46270 | B12: วันเสาร์
A13: =A12+1 -> 46271 | B13: วันอาทิตย์
A14: =A13+1 -> 46272
A15: =A14+1 -> 46273
A16: =A15+1 -> 46274
A17: =A16+1 -> 46275
A18: =A17+1 -> 46276
A19: =A18+1 -> 46277 | B19: วันเสาร์
A20: =A19+1 -> 46278 | B20: วันอาทิตย์
A21: =A20+1 -> 46279
A22: =A21+1 -> 46280
A23: =A22+1 -> 46281
A24: =A23+1 -> 46282
A25: =A24+1 -> 46283
A26: =A25+1 -> 46284 | B26: วันเสาร์
A27: =A26+1 -> 46285 | B27: วันอาทิตย์
A28: =A27+1 -> 46286
A29: =A28+1 -> 46287
A30: =A29+1 -> 46288
A31: =A30+1 -> 46289
A32: =A31+1 -> 46290
A33: =A32+1 -> 46291 | B33: วันเสาร์
A34: =A33+1 -> 46292 | B34: วันอาทิตย์
A35: =A34+1 -> 46293
A36: =A35+1 -> 46294
A37: =A36+1 -> 46295
B39: วันเข้าปฎิบัตงาน | C39: =COUNTIF($B$8:$B$37, "เข้าปฎิบัติงาน") -> 0 | D39: วันหยุด | E39: =SUM(COUNTIF($B$8:$B$37, {"วันเสาร์","วันอาทิตย์","วันหยุดนักขัตฤกษ์"})) -> 8
B40: วันไม่เข้าปฎิบัตงาน | C40: =COUNTIF($B$8:$B$37, "ไม่เข้าปฎิบัติงาน") -> 0 | D40: อื่นๆ | E40: =COUNTIF($B$8:$B$37, "อื่นๆ โปรดระบุรายละเอียด ") -> 0
D43: Review by | G43: Approve by
A44: ลงชื่อ ............................................... | D44: ลงชื่อ ............................................... | G44: ลงชื่อ ...............................................
A45: =B5 -> บุรพล อัศววิรุฬห์ฤทธิ์ | D45: =January!$F43 -> คุณสายฝน นามกูล | G45: =January!$H43 -> คุณอัจฉรา ชัยภูมิ
...

Sheet October
A1: =January!A1 -> รายงานการปฏิบัติงาน
A2: =January!A2 -> บริษัท ไอที ดี จำกัด
C3: ประจำวันที่ | D3: =DAY(A8)&" "&CHOOSE(MONTH(A8),"มกราคม","กุมภาพันธ์","มีนาคม","เมษายน","พฤษภาคม","มิถุนายน","กรกฎาคม","สิงหาคม","กันยายน","ตุลาคม","พฤศจิกายน","ธันวาคม")&" "&YEAR(A8)+543&" ถึง "&DAY(A38)&" "&CHOOSE(MONTH(A38),"มกราคม","กุมภาพันธ์","มีนาคม","เมษายน","พฤษภาคม","มิถุนายน","กรกฎาคม","สิงหาคม","กันยายน","ตุลาคม","พฤศจิกายน","ธันวาคม")&" "&YEAR(A38)+543 -> 1 ตุลาคม 2569 ถึง 31 ตุลาคม 2569
A5: ชื่อ - นามสกุล | B5: =January!B5 -> บุรพล อัศววิรุฬห์ฤทธิ์ | D5: โครงการ | E5: =January!E5 -> Fast Track
A7: วันที่ | B7: การปฎิบัติงาน | C7: รหัสงาน | D7: ประเภทงาน | E7: รายละเอียดของงานที่ทำ
A8: 46296
A9: =A8+1 -> 46297
A10: =A9+1 -> 46298 | B10: วันเสาร์
A11: =A10+1 -> 46299 | B11: วันอาทิตย์
A12: =A11+1 -> 46300
A13: =A12+1 -> 46301
A14: =A13+1 -> 46302
A15: =A14+1 -> 46303
A16: =A15+1 -> 46304
A17: =A16+1 -> 46305 | B17: วันเสาร์
A18: =A17+1 -> 46306 | B18: วันอาทิตย์
A19: =A18+1 -> 46307
A20: =A19+1 -> 46308 | B20: วันหยุดนักขัตฤกษ์
A21: =A20+1 -> 46309
A22: =A21+1 -> 46310
A23: =A22+1 -> 46311
A24: =A23+1 -> 46312 | B24: วันเสาร์
A25: =A24+1 -> 46313 | B25: วันอาทิตย์
A26: =A25+1 -> 46314
A27: =A26+1 -> 46315
A28: =A27+1 -> 46316
A29: =A28+1 -> 46317
A30: =A29+1 -> 46318 | B30: วันหยุดนักขัตฤกษ์
A31: =A30+1 -> 46319 | B31: วันเสาร์
A32: =A31+1 -> 46320 | B32: วันอาทิตย์
A33: =A32+1 -> 46321
A34: =A33+1 -> 46322
A35: =A34+1 -> 46323
A36: =A35+1 -> 46324
A37: =A36+1 -> 46325
A38: =A37+1 -> 46326 | B38: วันเสาร์
B40: วันเข้าปฎิบัตงาน | C40: =COUNTIF($B$8:$B$38, "เข้าปฎิบัติงาน") -> 0 | D40: วันหยุด | E40: =SUM(COUNTIF($B$8:$B$38, {"วันเสาร์","วันอาทิตย์","วันหยุดนักขัตฤกษ์"})) -> 11
B41: วันไม่เข้าปฎิบัตงาน | C41: =COUNTIF($B$8:$B$38, "ไม่เข้าปฎิบัติงาน") -> 0 | D41: อื่นๆ | E41: =COUNTIF($B$8:$B$38, "อื่นๆ โปรดระบุรายละเอียด ") -> 0
D43: Review by | G43: Approve by
A44: ลงชื่อ ............................................... | D44: ลงชื่อ ............................................... | G44: ลงชื่อ ...............................................
...

Sheet November
A1: =January!A1 -> รายงานการปฏิบัติงาน
A2: =January!A2 -> บริษัท ไอที ดี จำกัด
C3: ประจำวันที่ | D3: =DAY(A8)&" "&CHOOSE(MONTH(A8),"มกราคม","กุมภาพันธ์","มีนาคม","เมษายน","พฤษภาคม","มิถุนายน","กรกฎาคม","สิงหาคม","กันยายน","ตุลาคม","พฤศจิกายน","ธันวาคม")&" "&YEAR(A8)+543&" ถึง "&DAY(A37)&" "&CHOOSE(MONTH(A37),"มกราคม","กุมภาพันธ์","มีนาคม","เมษายน","พฤษภาคม","มิถุนายน","กรกฎาคม","สิงหาคม","กันยายน","ตุลาคม","พฤศจิกายน","ธันวาคม")&" "&YEAR(A37)+543 -> 1 พฤศจิกายน 2569 ถึง 30 พฤศจิกายน 2569
A5: ชื่อ - นามสกุล | B5: =January!B5 -> บุรพล อัศววิรุฬห์ฤทธิ์ | D5: โครงการ | E5: =January!E5 -> Fast Track
A7: วันที่ | B7: การปฎิบัติงาน | C7: รหัสงาน | D7: ประเภทงาน | E7: รายละเอียดของงานที่ทำ
A8: 46327 | B8: วันอาทิตย์
A9: =A8+1 -> 46328
A10: =A9+1 -> 46329
A11: =A10+1 -> 46330
A12: =A11+1 -> 46331
A13: =A12+1 -> 46332
A14: =A13+1 -> 46333 | B14: วันเสาร์
A15: =A14+1 -> 46334 | B15: วันอาทิตย์
A16: =A15+1 -> 46335
A17: =A16+1 -> 46336
A18: =A17+1 -> 46337
A19: =A18+1 -> 46338
A20: =A19+1 -> 46339
A21: =A20+1 -> 46340 | B21: วันเสาร์
A22: =A21+1 -> 46341 | B22: วันอาทิตย์
A23: =A22+1 -> 46342
A24: =A23+1 -> 46343
A25: =A24+1 -> 46344
A26: =A25+1 -> 46345
A27: =A26+1 -> 46346
A28: =A27+1 -> 46347 | B28: วันเสาร์
A29: =A28+1 -> 46348 | B29: วันอาทิตย์
A30: =A29+1 -> 46349
A31: =A30+1 -> 46350
A32: =A31+1 -> 46351
A33: =A32+1 -> 46352
A34: =A33+1 -> 46353
A35: =A34+1 -> 46354 | B35: วันเสาร์
A36: =A35+1 -> 46355 | B36: วันอาทิตย์
A37: =A36+1 -> 46356
B39: วันเข้าปฎิบัตงาน | C39: =COUNTIF($B$8:$B$37, "เข้าปฎิบัติงาน") -> 0 | D39: วันหยุด | E39: =SUM(COUNTIF($B$8:$B$37, {"วันเสาร์","วันอาทิตย์","วันหยุดนักขัตฤกษ์"})) -> 9
B40: วันไม่เข้าปฎิบัตงาน | C40: =COUNTIF($B$8:$B$37, "ไม่เข้าปฎิบัติงาน") -> 0 | D40: อื่นๆ | E40: =COUNTIF($B$8:$B$37, "อื่นๆ โปรดระบุรายละเอียด ") -> 0
D43: Review by | G43: Approve by
A44: ลงชื่อ ............................................... | D44: ลงชื่อ ............................................... | G44: ลงชื่อ ...............................................
A45: =B5 -> บุรพล อัศววิรุฬห์ฤทธิ์ | D45: =January!$F43 -> คุณสายฝน นามกูล | G45: =January!$H43 -> คุณอัจฉรา ชัยภูมิ
...

Sheet December
A1: =January!A1 -> รายงานการปฏิบัติงาน
A2: =January!A2 -> บริษัท ไอที ดี จำกัด
C3: ประจำวันที่ | D3: =DAY(A8)&" "&CHOOSE(MONTH(A8),"มกราคม","กุมภาพันธ์","มีนาคม","เมษายน","พฤษภาคม","มิถุนายน","กรกฎาคม","สิงหาคม","กันยายน","ตุลาคม","พฤศจิกายน","ธันวาคม")&" "&YEAR(A8)+543&" ถึง "&DAY(A38)&" "&CHOOSE(MONTH(A38),"มกราคม","กุมภาพันธ์","มีนาคม","เมษายน","พฤษภาคม","มิถุนายน","กรกฎาคม","สิงหาคม","กันยายน","ตุลาคม","พฤศจิกายน","ธันวาคม")&" "&YEAR(A38)+543 -> 1 ธันวาคม 2569 ถึง 31 ธันวาคม 2569
A5: ชื่อ - นามสกุล | B5: =January!B5 -> บุรพล อัศววิรุฬห์ฤทธิ์ | D5: โครงการ | E5: =January!E5 -> Fast Track
A7: วันที่ | B7: การปฎิบัติงาน | C7: รหัสงาน | D7: ประเภทงาน | E7: รายละเอียดของงานที่ทำ
A8: 46357
A9: =A8+1 -> 46358
A10: =A9+1 -> 46359
A11: =A10+1 -> 46360
A12: =A11+1 -> 46361 | B12: วันเสาร์
A13: =A12+1 -> 46362 | B13: วันอาทิตย์
A14: =A13+1 -> 46363 | B14: วันหยุดนักขัตฤกษ์
A15: =A14+1 -> 46364
A16: =A15+1 -> 46365
A17: =A16+1 -> 46366 | B17: วันหยุดนักขัตฤกษ์
A18: =A17+1 -> 46367
A19: =A18+1 -> 46368 | B19: วันเสาร์
A20: =A19+1 -> 46369 | B20: วันอาทิตย์
A21: =A20+1 -> 46370
A22: =A21+1 -> 46371
A23: =A22+1 -> 46372
A24: =A23+1 -> 46373
A25: =A24+1 -> 46374
A26: =A25+1 -> 46375 | B26: วันเสาร์
A27: =A26+1 -> 46376 | B27: วันอาทิตย์
A28: =A27+1 -> 46377
A29: =A28+1 -> 46378
A30: =A29+1 -> 46379
A31: =A30+1 -> 46380
A32: =A31+1 -> 46381
A33: =A32+1 -> 46382 | B33: วันเสาร์
A34: =A33+1 -> 46383 | B34: วันอาทิตย์
A35: =A34+1 -> 46384
A36: =A35+1 -> 46385
A37: =A36+1 -> 46386
A38: =A37+1 -> 46387 | B38: วันหยุดนักขัตฤกษ์
B40: วันเข้าปฎิบัตงาน | C40: =COUNTIF($B$8:$B$38, "เข้าปฎิบัติงาน") -> 0 | D40: วันหยุด | E40: =SUM(COUNTIF($B$8:$B$38, {"วันเสาร์","วันอาทิตย์","วันหยุดนักขัตฤกษ์"})) -> 11
B41: วันไม่เข้าปฎิบัตงาน | C41: =COUNTIF($B$8:$B$38, "ไม่เข้าปฎิบัติงาน") -> 0 | D41: อื่นๆ | E41: =COUNTIF($B$8:$B$38, "อื่นๆ โปรดระบุรายละเอียด ") -> 0
D43: Review by | G43: Approve by
A44: ลงชื่อ ............................................... | D44: ลงชื่อ ............................................... | G44: ลงชื่อ ...............................................
...
